Workbook

Sheet Summary
A1: Sherway Gardens – Hiring Platform Summary
A2: Built from the three store lists (Store-1, Store-2, Store-3), de-duplicated by store name.
A4: Platform Type | B4: # Stores | C4: % of Stores | D4: What it means
A5: Parent-company portal | B5: =COUNTIF('All Stores'!$B$2:$B$235,A5) -> 43 | C5: =B5/$B$10 -> 0.18376068 | D5: One portal posts jobs for several brands; apply to the company, then pick a store/location.
A6: Dedicated careers subdomain | B6: =COUNTIF('All Stores'!$B$2:$B$235,A6) -> 26 | C6: =B6/$B$10 -> 0.11111111 | D6: Own jobs./careers. site (e.g. jobs.bell.ca); typically a hosted applicant-tracking system.
A7: Careers page on store website | B7: =COUNTIF('All Stores'!$B$2:$B$235,A7) -> 82 | C7: =B7/$B$10 -> 0.35042735 | D7: A /careers page on the retailer's own site; may be a full job board or just an email/form.
A8: Shopify-style careers page | B8: =COUNTIF('All Stores'!$B$2:$B$235,A8) -> 20 | C8: =B8/$B$10 -> 0.085470085 | D8: Address ends in /pages/careers (common for smaller Shopify-based brands); often few roles or email applications.
A9: No career page listed | B9: =COUNTIF('All Stores'!$B$2:$B$235,A9) -> 63 | C9: =B9/$B$10 -> 0.26923077 | D9: Mostly small local or food/service shops; likely Indeed, Job Bank, Kijiji, social media or in-store signs (assumption, not in the data).
A10: Total | B10: =SUM(B5:B9) -> 234 | C10: =SUM(C5:C9) -> 1
A12: Stores whose career links differ between files | B12: =COUNTIF('All Stores'!$F$2:$F$235,"Yes") -> 43
A13: Stores with a career page listed | B13: =B10-B9 -> 171
A15: Notes
A16: • Categories are mutually exclusive. A store on a shared parent portal is counted there, not under subdomain/own site.
A17: • Platform type is inferred from the career link only. The actual software (Workday, Taleo, Lever, etc.) was not verified.
A18: • Duplicates across files were matched on the first 8 letters of the store name, so a few near-duplicates may remain.
A19: • Where files give different links for the same store, the first one is used and the rest appear on All Stores.

Sheet All Stores
A1: Store | B1: Platform Type | C1: Parent Portal / Group Site | D1: Career Page Link | E1: Other Link(s) in Other Files | F1: Links Differ? | G1: Official Website | H1: Category | I1: Found In
A2: Aerie | B2: Parent-company portal | C2: aeo-inc.com | D2: https://www.aeo-inc.com/careers/ | E2: https://www.ae.com/careers/ | F2: Yes | G2: https://www.ae.com/aerie | H2: Lingerie/Apparel | I2: Store-1, Store-2, Store-3
A3: American Eagle Outfitters | B3: Parent-company portal | C3: aeo-inc.com | D3: https://www.aeo-inc.com/careers/ | E3: https://www.ae.com/careers/ | F3: Yes | G3: https://www.ae.com | H3: Clothing | I3: Store-1, Store-2, Store-3
A4: Aldo | B4: Parent-company portal | C4: aldogroup.com | D4: https://www.aldogroup.com/careers | G4: https://www.aldoshoes.com | H4: Footwear | I4: Store-1, Store-2, Store-3
A5: B2 | B5: Parent-company portal | C5: aldogroup.com | D5: https://www.aldogroup.com/careers | G5: https://www.aldoshoes.com | H5: Footwear | I5: Store-1, Store-3
A6: Little Burgundy | B6: Parent-company portal | C6: aldogroup.com | D6: https://www.aldogroup.com/careers | G6: https://www.littleburgundyshoes.com | H6: Footwear | I6: Store-1, Store-3
A7: Aritzia | B7: Parent-company portal | C7: aritzia.com | D7: https://www.aritzia.com/en/careers | G7: https://www.aritzia.com | H7: Women's Clothing | I7: Store-1, Store-2, Store-3
A8: Wilfred (Aritzia) | B8: Parent-company portal | C8: aritzia.com | D8: https://www.aritzia.com/en/careers | G8: https://www.aritzia.com | H8: Women's Clothing | I8: Store-1
A9: Browns | B9: Parent-company portal | C9: brownsshoes.com | D9: https://www.brownsshoes.com/careers | G9: https://www.brownsshoes.com/ | H9: Footwear | I9: Store-3
A10: Browns Shoes | B10: Parent-company portal | C10: brownsshoes.com | D10: https://www.brownsshoes.com/pages/careers | G10: https://www.brownsshoes.com | H10: Footwear | I10: Store-1, Store-2
A11: Calzedonia | B11: Parent-company portal | C11: careers.calzedoniagroup.com | D11: https://careers.calzedoniagroup.com | G11: https://www.calzedonia.com | H11: Apparel & Legwear | I11: Store-2
A12: Intimissimi | B12: Parent-company portal | C12: careers.calzedoniagroup.com | D12: https://careers.calzedoniagroup.com | G12: https://www.intimissimi.com | H12: Apparel & Intimates | I12: Store-2
A13: LensCrafters | B13: Parent-company portal | C13: careers.essilorluxottica.com | D13: https://careers.essilorluxottica.com | E13: https://www.essilorluxottica.com/careers | F13: Yes | G13: https://www.lenscrafters.ca | H13: Glasses & Contact Lenses | I13: Store-1, Store-3
A14: Sunglass Hut | B14: Parent-company portal | C14: careers.essilorluxottica.com | D14: https://careers.essilorluxottica.com | E14: https://www.essilorluxottica.com/careers | F14: Yes | G14: https://www.sunglasshut.com | H14: Sunglasses | I14: Store-1, Store-3
A15: Champs Sports | B15: Parent-company portal | C15: careers.footlocker.com | D15: https://careers.footlocker.com | E15: https://jobs.footlocker.com/ | F15: Yes | G15: https://www.champssports.com | H15: Sporting Goods | I15: Store-1, Store-2, Store-3
A16: Foot Locker | B16: Parent-company portal | C16: careers.footlocker.com | D16: https://careers.footlocker.com | E16: https://jobs.footlocker.com/ | F16: Yes | G16: https://www.footlocker.ca | H16: Athletic Shoes & Apparel | I16: Store-1, Store-3
A17: Athleta | B17: Parent-company portal | C17: gapinc.com | D17: https://www.gapinc.com/en-us/careers | G17: https://athleta.gapcanada.ca | H17: Athletic Clothing | I17: Store-1, Store-2, Store-3
A18: Banana Republic | B18: Parent-company portal | C18: gapinc.com | D18: https://www.gapinc.com/en-us/careers | G18: https://bananarepublic.gapcanada.ca | H18: Apparel | I18: Store-1, Store-2, Store-3
A19: Gap / GapKids | B19: Parent-company portal | C19: gapinc.com | D19: https://www.gapinc.com/en-us/careers | G19: https://www.gapcanada.ca | H19: Clothing | I19: Store-1, Store-3
A20: Indigo | B20: Parent-company portal | C20: indigo.ca | D20: https://www.indigo.ca/en-ca/careers | G20: https://www.indigo.ca | H20: Books | I20: Store-1, Store-3
A21: Indigobaby | B21: Parent-company portal | C21: indigo.ca | D21: https://www.indigo.ca/en-ca/careers | G21: https://www.indigo.ca | H21: Children's Clothing | I21: Store-1
A22: Bell | B22: Parent-company portal | C22: jobs.bell.ca | D22: https://jobs.bell.ca | G22: https://www.bell.ca | H22: Telecom / Electronics | I22: Store-1, Store-2, Store-3
A23: Virgin Plus | B23: Parent-company portal | C23: jobs.bell.ca | D23: https://jobs.bell.ca | G23: https://www.virginplus.ca | H23: Cellular | I23: Store-1
A24: Aveda | B24: Parent-company portal | C24: jobs.elcompanies.com | D24: https://jobs.elcompanies.com | E24: https://www.elcompanies.com/en/careers https://www.aveda.com/careers | F24: Yes | G24: https://www.aveda.com | H24: Health & Beauty | I24: Store-1, Store-2, Store-3
A25: Kiehl's | B25: Parent-company portal | C25: jobs.elcompanies.com | D25: https://jobs.elcompanies.com | E25: https://www.loreal.com/en/careers/ | F25: Yes | G25: https://www.kiehls.com | H25: Beauty | I25: Store-1, Store-3
A26: MAC Cosmetics | B26: Parent-company portal | C26: jobs.elcompanies.com | D26: https://jobs.elcompanies.com | E26: https://www.elcompanies.com/careers | F26: Yes | G26: https://www.maccosmetics.ca | H26: Cosmetics / Skin Care | I26: Store-1, Store-3
A27: Fido | B27: Parent-company portal | C27: jobs.rogers.com | D27: https://jobs.rogers.com | G27: https://www.fido.ca | H27: Cellular | I27: Store-1, Store-3
A28: Rogers | B28: Parent-company portal | C28: jobs.rogers.com | D28: https://jobs.rogers.com | G28: https://www.rogers.com | H28: Telecom | I28: Store-1, Store-3
A29: JOEY Restaurants | B29: Parent-company portal | C29: joeyrestaurants.com | D29: https://joeyrestaurants.com/careers/ | G29: https://joeyrestaurants.com/ | H29: Restaurants | I29: Store-3
A30: JOEY Sherway | B30: Parent-company portal | C30: joeyrestaurants.com | D30: https://www.joeyrestaurants.com/careers | G30: https://www.joeyrestaurants.com | H30: Restaurant | I30: Store-1
A31: The Keg | B31: Parent-company portal | C31: kegsteakhouse.com | D31: https://www.kegsteakhouse.com/careers/ | G31: https://www.kegsteakhouse.com/ | H31: Restaurants | I31: Store-3
A32: The Keg Steakhouse + Bar | B32: Parent-company portal | C32: kegsteakhouse.com | D32: https://www.kegsteakhouse.com/en/careers | G32: https://www.kegsteakhouse.com | H32: Restaurant | I32: Store-1
A33: Lego | B33: Parent-company portal | C33: lego.com | D33: https://www.lego.com/en-us/careers | G33: https://www.lego.com | H33: Toys & Games | I33: Store-1
A34: The LEGO Store | B34: Parent-company portal | C34: lego.com | D34: https://www.lego.com/en-ca/careers | G34: https://www.lego.com/ | H34: Toys and Hobbies | I34: Store-3
A35: Tag Heuer | B35: Parent-company portal | C35: lvmh.com | D35: https://www.lvmh.com/en/talents | G35: https://www.tagheuer.com | H35: Watches | I35: Store-1
A36: Tiffany & Co. | B36: Parent-company portal | C36: lvmh.com | D36: https://www.lvmh.com/en/talents | G36: https://www.tiffany.com | H36: Jewelry | I36: Store-1
A37: Maje | B37: Parent-company portal | C37: smcp.com | D37: https://www.smcp.com/en/careers | G37: https://ca.maje.com | H37: Women's Clothing | I37: Store-1, Store-3
A38: Sandro | B38: Parent-company portal | C38: smcp.com | D38: https://www.smcp.com/en/careers | G38: https://ca.sandro-paris.com | H38: Clothing | I38: Store-1, Store-3
... A41: Kate Spade New York | B41: Parent-company portal | C41: tapestry.com | D41: https://www.tapestry.com/careers/ | G41: https://www.katespade.com | H41: Accessories | I41: Store-1
A42: TUMI | B42: Parent-company portal | C42: tapestry.com | D42: https://www.tapestry.com/careers/ | E42: https://www.tumi.com/careers | F42: Yes | G42: https://www.tumi.com | H42: Luggage, Handbags & Backpacks | I42: Store-1, Store-3
...

Sheet Parent Portals
A1: Portal (career site) | B1: Stores Covered | C1: # Stores in Lists
A2: aldogroup.com | B2: Aldo, B2, Little Burgundy | C2: =COUNTIF('All Stores'!$C$2:$C$235,A2) -> 3
A3: gapinc.com | B3: Athleta, Banana Republic, Gap / GapKids | C3: =COUNTIF('All Stores'!$C$2:$C$235,A3) -> 3
A4: jobs.elcompanies.com | B4: Aveda, Kiehl's, MAC Cosmetics | C4: =COUNTIF('All Stores'!$C$2:$C$235,A4) -> 3
A5: aeo-inc.com | B5: Aerie, American Eagle Outfitters | C5: =COUNTIF('All Stores'!$C$2:$C$235,A5) -> 2
A6: aritzia.com | B6: Aritzia, Wilfred (Aritzia) | C6: =COUNTIF('All Stores'!$C$2:$C$235,A6) -> 2
A7: brownsshoes.com | B7: Browns, Browns Shoes | C7: =COUNTIF('All Stores'!$C$2:$C$235,A7) -> 2
A8: careers.calzedoniagroup.com | B8: Calzedonia, Intimissimi | C8: =COUNTIF('All Stores'!$C$2:$C$235,A8) -> 2
A9: careers.essilorluxottica.com | B9: LensCrafters, Sunglass Hut | C9: =COUNTIF('All Stores'!$C$2:$C$235,A9) -> 2
A10: careers.footlocker.com | B10: Champs Sports, Foot Locker | C10: =COUNTIF('All Stores'!$C$2:$C$235,A10) -> 2
A11: indigo.ca | B11: Indigo, Indigobaby | C11: =COUNTIF('All Stores'!$C$2:$C$235,A11) -> 2
A12: jobs.bell.ca | B12: Bell, Virgin Plus | C12: =COUNTIF('All Stores'!$C$2:$C$235,A12) -> 2
A13: jobs.rogers.com | B13: Fido, Rogers | C13: =COUNTIF('All Stores'!$C$2:$C$235,A13) -> 2
... A21: williams-sonomainc.com | B21: Pottery Barn, Williams-Sonoma | C21: =COUNTIF('All Stores'!$C$2:$C$235,A21) -> 2

Sheet Dedicated Subdomains
A1: Store | B1: Careers Site
A2: Abercrombie & Fitch / abercrombie kids | B2: https://careers.anfcorp.com
A3: Adidas | B3: https://careers.adidas-group.com
A4: Bath & Body Works | B4: https://careers.bbwinc.com
A5: Best Buy Express | B5: https://jobs.bestbuy.com/
A6: Chipotle | B6: https://jobs.chipotle.com
A7: Claire's | B7: https://careers.claires.com
A8: Club Monaco | B8: https://careers.ralphlauren.com
A9: ECCO | B9: https://careers.ecco.com
A10: Experience RBC | B10: https://jobs.rbc.com
A11: H&M | B11: https://career.hm.com
A12: L'Occitane | B12: https://careers.loccitane.com
... A27: lululemon athletica | B27: https://careers.lululemon.com
